Workbook
Name BALcellPtNum: DB!$H$3:$H$1048576
Name BALptNum: DB!$H$3:$H$1048576
Name BatteryConfig: DB!$J$3:$J$1048576
Name BMSmfg: DB!$F$3:$F$1048576
Name BMSsupplier: DB!$D$3:$D$1048576
Name Cellchem: DB!#REF!
Name Cellmfg: DB!$H$3:$H$1048576
Name CellType: DB!#REF!
Name PackSupplier: DB!$L$3:$L$1048576

Sheet Rev History
A1: Revision History
A3: Version | B3: Date | C3: Prepared by | D3: Reviewed by | E3: Approved by | G3: Reason for modification
A5: 0.0.1 | B5: 44082 | C5: Aneesh Bhir | F5: 1 | G5: Original.
A6: 0.0.2 | B6: 44085 | C6: Aneesh Bhir | F6: 1 | G6: Added BINuniverse sheet. Here: - one can select parameters and arrive at a BIN. - sanity checks for each parameter are applied.
A7: 0.0.3 | B7: 44599 | C7: Vikram Jain | G7: Added new Battery pack and BMS supplier for Gotion
A8: 0.0.4 | B8: 45478 | C8: Aditya Tanwar
A9: 0.0.5 | B9: 45882 | C9: Abhishek/Aditya
A10: 0.0.6 | B10: 46147 | C10: Asma Khan | G10: Added new battery packs from Gotion 12.1 kWh 9.2 kWh 12.2 kWh 9.2 kWh (Side lug mounting) 12.1kWh (Side lug mounting) 10.3 kWh (Prismatic) 13.72 kWh (Prismatic) 10.3 kWh (Heater) 13.72 kWh (Heater) 6.1kWh 6.8kWh

Sheet Documentation
A1: Title
A2: Designer
A3: E-mail
A4: Approved by
A5: Company
A6: Department
A8: List of Abbreviations
A9: BIN | B9: Battery Identification Number
A13: Document Structure
A14: Type | B14: Section name/Text/LaTex/Table Name/Chart Name/Figure File Name | C14: Label | D14: Caption
B15: Introduction

Sheet Format
B1: =SUMPRODUCT(MAX((A:A<>"")*(ROW(A:A)))) -> 6
A2: Parameter | B2: Battery Capacity | H2: BatteryVariant | V2: PackSupplier | AB2: AssemblyInfo | AT2: Plant line | BD2: SerialNumber
A3: Format | C3: Hex | H3: BMSsupplier | I3: BMSmfg | J3: BALcellPartNum | K3: BatteryConfig | L3: FullName | M3: Hex | V3: Name | W3: Hex | AB3: YYYYMMDD | AC3: Hex | AD3: Year | AK3: Month | AO3: Date | AU3: Hex | BD3: # | BE3: Hex
A4: Min | C4: =DEC2HEX(0,1) -> 0 | D4: 0 | E4: 0 | F4: 0 | G4: 0 | AB4: 20000101 | AC4: 0021 | AD4: 0 | AE4: 0 | AF4: 0 | AG4: 0 | AH4: 0 | AI4: 0 | AJ4: 0 | AK4: 0 | AL4: 0 | AM4: 0 | AN4: 1 | AO4: 0 | AP4: 0 | AQ4: 0 | AR4: 0 | AS4: 1 | AT4: 0 | AU4: =DEC2HEX(AT4,1) -> 0 | AV4: 0 | AW4: 0 | AX4: 0 | AY4: 0 | AZ4: 0 | BA4: 0 | BB4: 0 | BC4: 0 | BD4: =HEX2DEC(BE4) -> 0 | BE4: =DEC2HEX(0,4) -> 0000 | BF4: 0 | BG4: 0 | BH4: 0 | BI4: 0 | BJ4: 0 | BK4: 0 | BL4: 0 | BM4: 0 | BN4: 0 | BO4: 0 | BP4: 0 | BQ4: 0 | BR4: 0 | BS4: 0 | BT4: 0 | BU4: 0
A5: Max | C5: =DEC2HEX(0,1) -> 0 | D5: 0 | E5: 0 | F5: 0 | G5: 0 | AB5: 21271231 | AC5: FF9F | AD5: 1 | AE5: 1 | AF5: 1 | AG5: 1 | AH5: 1 | AI5: 1 | AJ5: 1 | AK5: 1 | AL5: 1 | AM5: 0 | AN5: 0 | AO5: 1 | AP5: 1 | AQ5: 1 | AR5: 1 | AS5: 1 | AT5: 15 | AU5: =DEC2HEX(AT5,1) -> F | AV5: 0 | AW5: 0 | AX5: 0 | AY5: 0 | AZ5: 0 | BA5: 0 | BB5: 0 | BC5: 0 | BD5: =HEX2DEC(BE5) -> 65535 | BE5: =DEC2HEX(65535,4) -> FFFF | BF5: 1 | BG5: 1 | BH5: 1 | BI5: 1 | BJ5: 1 | BK5: 1 | BL5: 1 | BM5: 1 | BN5: 1 | BO5: 1 | BP5: 1 | BQ5: 1 | BR5: 1 | BS5: 1 | BT5: 1 | BU5: 1
A6: Enum | B6: Constant | C6: 0 | D6: =MID(HEX2BIN($C6,4),COLUMNS($C6:C6),1) -> 0 | E6: =MID(HEX2BIN($C6,4),COLUMNS($C6:D6),1) -> 0 | F6: =MID(HEX2BIN($C6,4),COLUMNS($C6:E6),1) -> 0 | G6: =MID(HEX2BIN($C6,4),COLUMNS($C6:F6),1) -> 0 | H6: RESERVED 1 | I6: RESERVED 3 | J6: RESERVED 1 | K6: FIX | L6: =IF(COUNTBLANK(H6:K6)>=1,CONCATENATE("Reserved",M6),CONCATENATE(H6,"_",I6,"_",J6,"_",K6)) -> RESERVED 1_RESERVED 3_RESERVED 1_FIX | M6: =DEC2HEX(ROW()-$B$1,2) -> 00 | N6: =MID(HEX2BIN($M6,8),COLUMNS($M6:M6),1) -> 0 | O6: =MID(HEX2BIN($M6,8),COLUMNS($M6:N6),1) -> 0 | P6: =MID(HEX2BIN($M6,8),COLUMNS($M6:O6),1) -> 0 | Q6: =MID(HEX2BIN($M6,8),COLUMNS($M6:P6),1) -> 0 | R6: =MID(HEX2BIN($M6,8),COLUMNS($M6:Q6),1) -> 0 | S6: =MID(HEX2BIN($M6,8),COLUMNS($M6:R6),1) -> 0 | T6: =MID(HEX2BIN($M6,8),COLUMNS($M6:S6),1) -> 0 | U6: =MID(HEX2BIN($M6,8),COLUMNS($M6:T6),1) -> 0 | V6: BAL R&D | W6: =DEC2HEX(ROW()-$B$1,1) -> 0 | X6: =MID(HEX2BIN($W6,4),COLUMNS($W6:W6),1) -> 0 | Y6: =MID(HEX2BIN($W6,4),COLUMNS($W6:X6),1) -> 0 | Z6: =MID(HEX2BIN($W6,4),COLUMNS($W6:Y6),1) -> 0 | AA6: =MID(HEX2BIN($W6,4),COLUMNS($W6:Z6),1) -> 0 | AB6: YYYY | AC6: 2025 | AV6: =MID(HEX2BIN($AU6,8),COLUMNS($AU6:AU6),1) -> 0 | AW6: =MID(HEX2BIN($AU6,8),COLUMNS($AT6:AT6),1) -> 0 | AX6: =MID(HEX2BIN($AU6,8),COLUMNS($AT6:AV6),1) -> 0 | AY6: =MID(HEX2BIN($AU6,8),COLUMNS($AT6:AW6),1) -> 0 | AZ6: =MID(HEX2BIN($AU6,8),COLUMNS($AT6:AX6),1) -> 0 | BA6: =MID(HEX2BIN($AU6,8),COLUMNS($AT6:AY6),1) -> 0 | BB6: =MID(HEX2BIN($AU6,8),COLUMNS($AT6:AZ6),1) -> 0 | BC6: =MID(HEX2BIN($AU6,8),COLUMNS($AT6:BA6),1) -> 0
C7: 1 | H7: RESERVED 1 | I7: RESERVED 3 | J7: RESERVED 2 | K7: FIX | L7: =IF(COUNTBLANK(H7:K7)>=1,CONCATENATE("Reserved",M7),CONCATENATE(H7,"_",I7,"_",J7,"_",K7)) -> RESERVED 1_RESERVED 3_RESERVED 2_FIX | M7: =DEC2HEX(ROW()-$B$1,2) -> 01 | N7: =MID(HEX2BIN($M7,8),COLUMNS($M7:M7),1) -> 0 | O7: =MID(HEX2BIN($M7,8),COLUMNS($M7:N7),1) -> 0 | P7: =MID(HEX2BIN($M7,8),COLUMNS($M7:O7),1) -> 0 | Q7: =MID(HEX2BIN($M7,8),COLUMNS($M7:P7),1) -> 0 | R7: =MID(HEX2BIN($M7,8),COLUMNS($M7:Q7),1) -> 0 | S7: =MID(HEX2BIN($M7,8),COLUMNS($M7:R7),1) -> 0 | T7: =MID(HEX2BIN($M7,8),COLUMNS($M7:S7),1) -> 0 | U7: =MID(HEX2BIN($M7,8),COLUMNS($M7:T7),1) -> 1 | V7: BAL | W7: =DEC2HEX(ROW()-$B$1,1) -> 1 | X7: =MID(HEX2BIN($W7,4),COLUMNS($W7:W7),1) -> 0 | Y7: =MID(HEX2BIN($W7,4),COLUMNS($W7:X7),1) -> 0 | Z7: =MID(HEX2BIN($W7,4),COLUMNS($W7:Y7),1) -> 0 | AA7: =MID(HEX2BIN($W7,4),COLUMNS($W7:Z7),1) -> 1 | AB7: MM | AC7: 9
C8: 2 | H8: GOTION | I8: PENERGY | J8: PRF027135_145 | K8: FIX | L8: =IF(COUNTBLANK(H8:K8)>=1,CONCATENATE("Reserved",M8),CONCATENATE(H8,"_",I8,"_",J8,"_",K8)) -> GOTION_PENERGY_PRF027135_145_FIX | M8: =DEC2HEX(ROW()-$B$1,2) -> 02 | N8: =MID(HEX2BIN($M8,8),COLUMNS($M8:M8),1) -> 0 | O8: =MID(HEX2BIN($M8,8),COLUMNS($M8:N8),1) -> 0 | P8: =MID(HEX2BIN($M8,8),COLUMNS($M8:O8),1) -> 0 | Q8: =MID(HEX2BIN($M8,8),COLUMNS($M8:P8),1) -> 0 | R8: =MID(HEX2BIN($M8,8),COLUMNS($M8:Q8),1) -> 0 | S8: =MID(HEX2BIN($M8,8),COLUMNS($M8:R8),1) -> 0 | T8: =MID(HEX2BIN($M8,8),COLUMNS($M8:S8),1) -> 1 | U8: =MID(HEX2BIN($M8,8),COLUMNS($M8:T8),1) -> 0 | V8: RESERVED 1 | W8: =DEC2HEX(ROW()-$B$1,1) -> 2 | X8: =MID(HEX2BIN($W8,4),COLUMNS($W8:W8),1) -> 0 | Y8: =MID(HEX2BIN($W8,4),COLUMNS($W8:X8),1) -> 0 | Z8: =MID(HEX2BIN($W8,4),COLUMNS($W8:Y8),1) -> 1 | AA8: =MID(HEX2BIN($W8,4),COLUMNS($W8:Z8),1) -> 0 | AB8: DD | AC8: 16
C9: 3 | H9: GOTION | I9: RNTEC | J9: GL405132_21 | K9: SWP | L9: =IF(COUNTBLANK(H9:K9)>=1,CONCATENATE("Reserved",M9),CONCATENATE(H9,"_",I9,"_",J9,"_",K9)) -> GOTION_RNTEC_GL405132_21_SWP | M9: =DEC2HEX(ROW()-$B$1,2) -> 03 | N9: =MID(HEX2BIN($M9,8),COLUMNS($M9:M9),1) -> 0 | O9: =MID(HEX2BIN($M9,8),COLUMNS($M9:N9),1) -> 0 | P9: =MID(HEX2BIN($M9,8),COLUMNS($M9:O9),1) -> 0 | Q9: =MID(HEX2BIN($M9,8),COLUMNS($M9:P9),1) -> 0 | R9: =MID(HEX2BIN($M9,8),COLUMNS($M9:Q9),1) -> 0 | S9: =MID(HEX2BIN($M9,8),COLUMNS($M9:R9),1) -> 0 | T9: =MID(HEX2BIN($M9,8),COLUMNS($M9:S9),1) -> 1 | U9: =MID(HEX2BIN($M9,8),COLUMNS($M9:T9),1) -> 1 | V9: GOTION | W9: =DEC2HEX(ROW()-$B$1,1) -> 3 | X9: =MID(HEX2BIN($W9,4),COLUMNS($W9:W9),1) -> 0 | Y9: =MID(HEX2BIN($W9,4),COLUMNS($W9:X9),1) -> 0 | Z9: =MID(HEX2BIN($W9,4),COLUMNS($W9:Y9),1) -> 1 | AA9: =MID(HEX2BIN($W9,4),COLUMNS($W9:Z9),1) -> 1 | AC9: =CONCATENATE(BIN2HEX(LEFT(CONCATENATE(DEC2BIN(AC6-2000,7),DEC2BIN(AC7,4),DEC2BIN(AC8,5)),4)),BIN2HEX(LEFT(RIGHT(CONCATENATE(DEC2BIN(AC6-2000,7),DEC2BIN(AC7,4),DEC2BIN(AC8,5)),12),4)),BIN2HEX(LEFT(RIGHT(CONCATENATE(DEC2BIN(AC6-2000,7),DEC2BIN(AC7,4),DEC2BIN(AC8,5)),8),4)),BIN2HEX(RIGHT(CONCATENATE(DEC2BIN(AC6-2000,7),DEC2BIN(AC7,4),DEC2BIN(AC8,5)),4))) -> 3330
C10: 5 | H10: RESERVED 1 | I10: RESERVED 3 | J10: RESERVED7 | K10: FIX | L10: =IF(COUNTBLANK(H10:K10)>=1,CONCATENATE("Reserved",M10),CONCATENATE(H10,"_",I10,"_",J10,"_",K10)) -> RESERVED 1_RESERVED 3_RESERVED7_FIX | M10: =DEC2HEX(ROW()-$B$1,2) -> 04 | N10: =MID(HEX2BIN($M10,8),COLUMNS($M10:M10),1) -> 0 | O10: =MID(HEX2BIN($M10,8),COLUMNS($M10:N10),1) -> 0 | P10: =MID(HEX2BIN($M10,8),COLUMNS($M10:O10),1) -> 0 | Q10: =MID(HEX2BIN($M10,8),COLUMNS($M10:P10),1) -> 0 | R10: =MID(HEX2BIN($M10,8),COLUMNS($M10:Q10),1) -> 0 | S10: =MID(HEX2BIN($M10,8),COLUMNS($M10:R10),1) -> 1 | T10: =MID(HEX2BIN($M10,8),COLUMNS($M10:S10),1) -> 0 | U10: =MID(HEX2BIN($M10,8),COLUMNS($M10:T10),1) -> 0 | V10: TACO-EV | W10: =DEC2HEX(ROW()-$B$1,1) -> 4 | X10: =MID(HEX2BIN($W10,4),COLUMNS($W10:W10),1) -> 0 | Y10: =MID(HEX2BIN($W10,4),COLUMNS($W10:X10),1) -> 1 | Z10: =MID(HEX2BIN($W10,4),COLUMNS($W10:Y10),1) -> 0 | AA10: =MID(HEX2BIN($W10,4),COLUMNS($W10:Z10),1) -> 0
C11: 4 | H11: RESERVED 1 | I11: RESERVED 3 | J11: RESERVED8 | K11: FIX | L11: =IF(COUNTBLANK(H11:K11)>=1,CONCATENATE("Reserved",M11),CONCATENATE(H11,"_",I11,"_",J11,"_",K11)) -> RESERVED 1_RESERVED 3_RESERVED8_FIX | M11: =DEC2HEX(ROW()-$B$1,2) -> 05 | N11: =MID(HEX2BIN($M11,8),COLUMNS($M11:M11),1) -> 0 | O11: =MID(HEX2BIN($M11,8),COLUMNS($M11:N11),1) -> 0 | P11: =MID(HEX2BIN($M11,8),COLUMNS($M11:O11),1) -> 0 | Q11: =MID(HEX2BIN($M11,8),COLUMNS($M11:P11),1) -> 0 | R11: =MID(HEX2BIN($M11,8),COLUMNS($M11:Q11),1) -> 0 | S11: =MID(HEX2BIN($M11,8),COLUMNS($M11:R11),1) -> 1 | T11: =MID(HEX2BIN($M11,8),COLUMNS($M11:S11),1) -> 0 | U11: =MID(HEX2BIN($M11,8),COLUMNS($M11:T11),1) -> 1 | V11: RESERVED 2 | W11: 5 | X11: =MID(HEX2BIN($W11,4),COLUMNS($W11:W11),1) -> 0 | Y11: =MID(HEX2BIN($W11,4),COLUMNS($W11:X11),1) -> 1 | Z11: =MID(HEX2BIN($W11,4),COLUMNS($W11:Y11),1) -> 0 | AA11: =MID(HEX2BIN($W11,4),COLUMNS($W11:Z11),1) -> 1
C12: 5 | H12: RESERVED 4 | I12: RESERVED 5 | J12: RESERVED9 | K12: FIX | L12: =IF(COUNTBLANK(H12:K12)>=1,CONCATENATE("Reserved",M12),CONCATENATE(H12,"_",I12,"_",J12,"_",K12)) -> RESERVED 4_RESERVED 5_RESERVED9_FIX | M12: =DEC2HEX(ROW()-$B$1,2) -> 06 | N12: =MID(HEX2BIN($M12,8),COLUMNS($M12:M12),1) -> 0 | O12: =MID(HEX2BIN($M12,8),COLUMNS($M12:N12),1) -> 0 | P12: =MID(HEX2BIN($M12,8),COLUMNS($M12:O12),1) -> 0 | Q12: =MID(HEX2BIN($M12,8),COLUMNS($M12:P12),1) -> 0 | R12: =MID(HEX2BIN($M12,8),COLUMNS($M12:Q12),1) -> 0 | S12: =MID(HEX2BIN($M12,8),COLUMNS($M12:R12),1) -> 1 | T12: =MID(HEX2BIN($M12,8),COLUMNS($M12:S12),1) -> 1 | U12: =MID(HEX2BIN($M12,8),COLUMNS($M12:T12),1) -> 0 | W12: =DEC2HEX(ROW()-$B$1,1) -> 6 | X12: =MID(HEX2BIN($W12,4),COLUMNS($W12:W12),1) -> 0 | Y12: =MID(HEX2BIN($W12,4),COLUMNS($W12:X12),1) -> 1 | Z12: =MID(HEX2BIN($W12,4),COLUMNS($W12:Y12),1) -> 1 | AA12: =MID(HEX2BIN($W12,4),COLUMNS($W12:Z12),1) -> 0
C13: 6 | H13: RESERVED 5 | I13: RESERVED 4 | J13: RESERVED10 | K13: FIX | L13: =IF(COUNTBLANK(H13:K13)>=1,CONCATENATE("Reserved",M13),CONCATENATE(H13,"_",I13,"_",J13,"_",K13)) -> RESERVED 5 _RESERVED 4_RESERVED10_FIX | M13: =DEC2HEX(ROW()-$B$1,2) -> 07 | N13: =MID(HEX2BIN($M13,8),COLUMNS($M13:M13),1) -> 0 | O13: =MID(HEX2BIN($M13,8),COLUMNS($M13:N13),1) -> 0 | P13: =MID(HEX2BIN($M13,8),COLUMNS($M13:O13),1) -> 0 | Q13: =MID(HEX2BIN($M13,8),COLUMNS($M13:P13),1) -> 0 | R13: =MID(HEX2BIN($M13,8),COLUMNS($M13:Q13),1) -> 0 | S13: =MID(HEX2BIN($M13,8),COLUMNS($M13:R13),1) -> 1 | T13: =MID(HEX2BIN($M13,8),COLUMNS($M13:S13),1) -> 1 | U13: =MID(HEX2BIN($M13,8),COLUMNS($M13:T13),1) -> 1 | W13: =DEC2HEX(ROW()-$B$1,1) -> 7 | X13: =MID(HEX2BIN($W13,4),COLUMNS($W13:W13),1) -> 0 | Y13: =MID(HEX2BIN($W13,4),COLUMNS($W13:X13),1) -> 1 | Z13: =MID(HEX2BIN($W13,4),COLUMNS($W13:Y13),1) -> 1 | AA13: =MID(HEX2BIN($W13,4),COLUMNS($W13:Z13),1) -> 1
C14: 7 | H14: BAL | I14: RESERVED 3 | J14: RESERVED 3 | K14: FIX | L14: =IF(COUNTBLANK(H14:K14)>=1,CONCATENATE("Reserved",M14),CONCATENATE(H14,"_",I14,"_",J14,"_",K14)) -> BAL_RESERVED 3_RESERVED 3_FIX | M14: =DEC2HEX(ROW()-$B$1,2) -> 08 | N14: =MID(HEX2BIN($M14,8),COLUMNS($M14:M14),1) -> 0 | O14: =MID(HEX2BIN($M14,8),COLUMNS($M14:N14),1) -> 0 | P14: =MID(HEX2BIN($M14,8),COLUMNS($M14:O14),1) -> 0 | Q14: =MID(HEX2BIN($M14,8),COLUMNS($M14:P14),1) -> 0 | R14: =MID(HEX2BIN($M14,8),COLUMNS($M14:Q14),1) -> 1 | S14: =MID(HEX2BIN($M14,8),COLUMNS($M14:R14),1) -> 0 | T14: =MID(HEX2BIN($M14,8),COLUMNS($M14:S14),1) -> 0 | U14: =MID(HEX2BIN($M14,8),COLUMNS($M14:T14),1) -> 0 | W14: =DEC2HEX(ROW()-$B$1,1) -> 8 | X14: =MID(HEX2BIN($W14,4),COLUMNS($W14:W14),1) -> 1 | Y14: =MID(HEX2BIN($W14,4),COLUMNS($W14:X14),1) -> 0 | Z14: =MID(HEX2BIN($W14,4),COLUMNS($W14:Y14),1) -> 0 | AA14: =MID(HEX2BIN($W14,4),COLUMNS($W14:Z14),1) -> 0
C15: 8 | H15: BAL | I15: RESERVED 3 | J15: RESERVED11 | K15: FIX | L15: =IF(COUNTBLANK(H15:K15)>=1,CONCATENATE("Reserved",M15),CONCATENATE(H15,"_",I15,"_",J15,"_",K15)) -> BAL_RESERVED 3_RESERVED11_FIX | M15: =DEC2HEX(ROW()-$B$1,2) -> 09 | N15: =MID(HEX2BIN($M15,8),COLUMNS($M15:M15),1) -> 0 | O15: =MID(HEX2BIN($M15,8),COLUMNS($M15:N15),1) -> 0 | P15: =MID(HEX2BIN($M15,8),COLUMNS($M15:O15),1) -> 0 | Q15: =MID(HEX2BIN($M15,8),COLUMNS($M15:P15),1) -> 0 | R15: =MID(HEX2BIN($M15,8),COLUMNS($M15:Q15),1) -> 1 | S15: =MID(HEX2BIN($M15,8),COLUMNS($M15:R15),1) -> 0 | T15: =MID(HEX2BIN($M15,8),COLUMNS($M15:S15),1) -> 0 | U15: =MID(HEX2BIN($M15,8),COLUMNS($M15:T15),1) -> 1 | W15: =DEC2HEX(ROW()-$B$1,1) -> 9 | X15: =MID(HEX2BIN($W15,4),COLUMNS($W15:W15),1) -> 1 | Y15: =MID(HEX2BIN($W15,4),COLUMNS($W15:X15),1) -> 0 | Z15: =MID(HEX2BIN($W15,4),COLUMNS($W15:Y15),1) -> 0 | AA15: =MID(HEX2BIN($W15,4),COLUMNS($W15:Z15),1) -> 1
C16: 9 | H16: BAL | I16: RESERVED 6 | J16: RESERVED 3 | K16: FIX | L16: =IF(COUNTBLANK(H16:K16)>=1,CONCATENATE("Reserved",M16),CONCATENATE(H16,"_",I16,"_",J16,"_",K16)) -> BAL_RESERVED 6_RESERVED 3_FIX | M16: =DEC2HEX(ROW()-$B$1,2) -> 0A | N16: =MID(HEX2BIN($M16,8),COLUMNS($M16:M16),1) -> 0 | O16: =MID(HEX2BIN($M16,8),COLUMNS($M16:N16),1) -> 0 | P16: =MID(HEX2BIN($M16,8),COLUMNS($M16:O16),1) -> 0 | Q16: =MID(HEX2BIN($M16,8),COLUMNS($M16:P16),1) -> 0 | R16: =MID(HEX2BIN($M16,8),COLUMNS($M16:Q16),1) -> 1 | S16: =MID(HEX2BIN($M16,8),COLUMNS($M16:R16),1) -> 0 | T16: =MID(HEX2BIN($M16,8),COLUMNS($M16:S16),1) -> 1 | U16: =MID(HEX2BIN($M16,8),COLUMNS($M16:T16),1) -> 0 | W16: =DEC2HEX(ROW()-$B$1,1) -> A | X16: =MID(HEX2BIN($W16,4),COLUMNS($W16:W16),1) -> 1 | Y16: =MID(HEX2BIN($W16,4),COLUMNS($W16:X16),1) -> 0 | Z16: =MID(HEX2BIN($W16,4),COLUMNS($W16:Y16),1) -> 1 | AA16: =MID(HEX2BIN($W16,4),COLUMNS($W16:Z16),1) -> 0
C17: 10 | H17: BAL | I17: RESERVED 6 | J17: RESERVED11 | K17: FIX | L17: =IF(COUNTBLANK(H17:K17)>=1,CONCATENATE("Reserved",M17),CONCATENATE(H17,"_",I17,"_",J17,"_",K17)) -> BAL_RESERVED 6_RESERVED11_FIX | M17: =DEC2HEX(ROW()-$B$1,2) -> 0B | N17: =MID(HEX2BIN($M17,8),COLUMNS($M17:M17),1) -> 0 | O17: =MID(HEX2BIN($M17,8),COLUMNS($M17:N17),1) -> 0 | P17: =MID(HEX2BIN($M17,8),COLUMNS($M17:O17),1) -> 0 | Q17: =MID(HEX2BIN($M17,8),COLUMNS($M17:P17),1) -> 0 | R17: =MID(HEX2BIN($M17,8),COLUMNS($M17:Q17),1) -> 1 | S17: =MID(HEX2BIN($M17,8),COLUMNS($M17:R17),1) -> 0 | T17: =MID(HEX2BIN($M17,8),COLUMNS($M17:S17),1) -> 1 | U17: =MID(HEX2BIN($M17,8),COLUMNS($M17:T17),1) -> 1 | W17: =DEC2HEX(ROW()-$B$1,1) -> B | X17: =MID(HEX2BIN($W17,4),COLUMNS($W17:W17),1) -> 1 | Y17: =MID(HEX2BIN($W17,4),COLUMNS($W17:X17),1) -> 0 | Z17: =MID(HEX2BIN($W17,4),COLUMNS($W17:Y17),1) -> 1 | AA17: =MID(HEX2BIN($W17,4),COLUMNS($W17:Z17),1) -> 1
C18: 11 | H18: BAL | I18: RESERVED 3 | J18: RESERVED12 | K18: FIX | L18: =IF(COUNTBLANK(H18:K18)>=1,CONCATENATE("Reserved",M18),CONCATENATE(H18,"_",I18,"_",J18,"_",K18)) -> BAL_RESERVED 3_RESERVED12_FIX | M18: =DEC2HEX(ROW()-$B$1,2) -> 0C | N18: =MID(HEX2BIN($M18,8),COLUMNS($M18:M18),1) -> 0 | O18: =MID(HEX2BIN($M18,8),COLUMNS($M18:N18),1) -> 0 | P18: =MID(HEX2BIN($M18,8),COLUMNS($M18:O18),1) -> 0 | Q18: =MID(HEX2BIN($M18,8),COLUMNS($M18:P18),1) -> 0 | R18: =MID(HEX2BIN($M18,8),COLUMNS($M18:Q18),1) -> 1 | S18: =MID(HEX2BIN($M18,8),COLUMNS($M18:R18),1) -> 1 | T18: =MID(HEX2BIN($M18,8),COLUMNS($M18:S18),1) -> 0 | U18: =MID(HEX2BIN($M18,8),COLUMNS($M18:T18),1) -> 0 | W18: =DEC2HEX(ROW()-$B$1,1) -> C | X18: =MID(HEX2BIN($W18,4),COLUMNS($W18:W18),1) -> 1 | Y18: =MID(HEX2BIN($W18,4),COLUMNS($W18:X18),1) -> 1 | Z18: =MID(HEX2BIN($W18,4),COLUMNS($W18:Y18),1) -> 0 | AA18: =MID(HEX2BIN($W18,4),COLUMNS($W18:Z18),1) -> 0
C19: 12 | H19: BAL | I19: RESERVED 6 | J19: RESERVED12 | K19: FIX | L19: =IF(COUNTBLANK(H19:K19)>=1,CONCATENATE("Reserved",M19),CONCATENATE(H19,"_",I19,"_",J19,"_",K19)) -> BAL_RESERVED 6_RESERVED12_FIX | M19: =DEC2HEX(ROW()-$B$1,2) -> 0D | N19: =MID(HEX2BIN($M19,8),COLUMNS($M19:M19),1) -> 0 | O19: =MID(HEX2BIN($M19,8),COLUMNS($M19:N19),1) -> 0 | P19: =MID(HEX2BIN($M19,8),COLUMNS($M19:O19),1) -> 0 | Q19: =MID(HEX2BIN($M19,8),COLUMNS($M19:P19),1) -> 0 | R19: =MID(HEX2BIN($M19,8),COLUMNS($M19:Q19),1) -> 1 | S19: =MID(HEX2BIN($M19,8),COLUMNS($M19:R19),1) -> 1 | T19: =MID(HEX2BIN($M19,8),COLUMNS($M19:S19),1) -> 0 | U19: =MID(HEX2BIN($M19,8),COLUMNS($M19:T19),1) -> 1 | W19: =DEC2HEX(ROW()-$B$1,1) -> D | X19: =MID(HEX2BIN($W19,4),COLUMNS($W19:W19),1) -> 1 | Y19: =MID(HEX2BIN($W19,4),COLUMNS($W19:X19),1) -> 1 | Z19: =MID(HEX2BIN($W19,4),COLUMNS($W19:Y19),1) -> 0 | AA19: =MID(HEX2BIN($W19,4),COLUMNS($W19:Z19),1) -> 1
C20: 13 | H20: GOTION | I20: PENERGY | J20: Gotion_14.8 | K20: FIX | L20: =IF(COUNTBLANK(H20:K20)>=1,CONCATENATE("Reserved",M20),CONCATENATE(H20,"_",I20,"_",J20,"_",K20)) -> GOTION_PENERGY_Gotion_14.8_FIX | M20: =DEC2HEX(ROW()-$B$1,2) -> 0E | N20: =MID(HEX2BIN($M20,8),COLUMNS($M20:M20),1) -> 0 | O20: =MID(HEX2BIN($M20,8),COLUMNS($M20:N20),1) -> 0 | P20: =MID(HEX2BIN($M20,8),COLUMNS($M20:O20),1) -> 0 | Q20: =MID(HEX2BIN($M20,8),COLUMNS($M20:P20),1) -> 0 | R20: =MID(HEX2BIN($M20,8),COLUMNS($M20:Q20),1) -> 1 | S20: =MID(HEX2BIN($M20,8),COLUMNS($M20:R20),1) -> 1 | T20: =MID(HEX2BIN($M20,8),COLUMNS($M20:S20),1) -> 1 | U20: =MID(HEX2BIN($M20,8),COLUMNS($M20:T20),1) -> 0 | W20: =DEC2HEX(ROW()-$B$1,1) -> E | X20: =MID(HEX2BIN($W20,4),COLUMNS($W20:W20),1) -> 1 | Y20: =MID(HEX2BIN($W20,4),COLUMNS($W20:X20),1) -> 1 | Z20: =MID(HEX2BIN($W20,4),COLUMNS($W20:Y20),1) -> 1 | AA20: =MID(HEX2BIN($W20,4),COLUMNS($W20:Z20),1) -> 0
C21: 14 | H21: GOTION | I21: PENERGY | J21: Gotion_67 | K21: FIX | L21: =IF(COUNTBLANK(H21:K21)>=1,CONCATENATE("Reserved",M21),CONCATENATE(H21,"_",I21,"_",J21,"_",K21)) -> GOTION_PENERGY_Gotion_67_FIX | M21: =DEC2HEX(ROW()-$B$1,2) -> 0F | N21: =MID(HEX2BIN($M21,8),COLUMNS($M21:M21),1) -> 0 | O21: =MID(HEX2BIN($M21,8),COLUMNS($M21:N21),1) -> 0 | P21: =MID(HEX2BIN($M21,8),COLUMNS($M21:O21),1) -> 0 | Q21: =MID(HEX2BIN($M21,8),COLUMNS($M21:P21),1) -> 0 | R21: =MID(HEX2BIN($M21,8),COLUMNS($M21:Q21),1) -> 1 | S21: =MID(HEX2BIN($M21,8),COLUMNS($M21:R21),1) -> 1 | T21: =MID(HEX2BIN($M21,8),COLUMNS($M21:S21),1) -> 1 | U21: =MID(HEX2BIN($M21,8),COLUMNS($M21:T21),1) -> 1 | W21: =DEC2HEX(ROW()-$B$1,1) -> F | X21: =MID(HEX2BIN($W21,4),COLUMNS($W21:W21),1) -> 1 | Y21: =MID(HEX2BIN($W21,4),COLUMNS($W21:X21),1) -> 1 | Z21: =MID(HEX2BIN($W21,4),COLUMNS($W21:Y21),1) -> 1 | AA21: =MID(HEX2BIN($W21,4),COLUMNS($W21:Z21),1) -> 1
C22: 15 | H22: GOTION | I22: DBG | J22: Gotion_14.8 | K22: FIX | L22: =IF(COUNTBLANK(H22:K22)>=1,CONCATENATE("Reserved",M22),CONCATENATE(H22,"_",I22,"_",J22,"_",K22)) -> GOTION_DBG_Gotion_14.8_FIX | M22: =DEC2HEX(ROW()-$B$1,2) -> 10 | N22: =MID(HEX2BIN($M22,8),COLUMNS($M22:M22),1) -> 0 | O22: =MID(HEX2BIN($M22,8),COLUMNS($M22:N22),1) -> 0 | P22: =MID(HEX2BIN($M22,8),COLUMNS($M22:O22),1) -> 0 | Q22: =MID(HEX2BIN($M22,8),COLUMNS($M22:P22),1) -> 1 | R22: =MID(HEX2BIN($M22,8),COLUMNS($M22:Q22),1) -> 0 | S22: =MID(HEX2BIN($M22,8),COLUMNS($M22:R22),1) -> 0 | T22: =MID(HEX2BIN($M22,8),COLUMNS($M22:S22),1) -> 0 | U22: =MID(HEX2BIN($M22,8),COLUMNS($M22:T22),1) -> 0
C23: 16 | M23: =DEC2HEX(ROW()-$B$1,2) -> 11 | N23: =MID(HEX2BIN($M23,8),COLUMNS($M23:M23),1) -> 0 | O23: =MID(HEX2BIN($M23,8),COLUMNS($M23:N23),1) -> 0 | P23: =MID(HEX2BIN($M23,8),COLUMNS($M23:O23),1) -> 0 | Q23: =MID(HEX2BIN($M23,8),COLUMNS($M23:P23),1) -> 1 | R23: =MID(HEX2BIN($M23,8),COLUMNS($M23:Q23),1) -> 0 | S23: =MID(HEX2BIN($M23,8),COLUMNS($M23:R23),1) -> 0 | T23: =MID(HEX2BIN($M23,8),COLUMNS($M23:S23),1) -> 0 | U23: =MID(HEX2BIN($M23,8),COLUMNS($M23:T23),1) -> 1
C24: 17 | M24: =DEC2HEX(ROW()-$B$1,2) -> 12 | N24: =MID(HEX2BIN($M24,8),COLUMNS($M24:M24),1) -> 0 | O24: =MID(HEX2BIN($M24,8),COLUMNS($M24:N24),1) -> 0 | P24: =MID(HEX2BIN($M24,8),COLUMNS($M24:O24),1) -> 0 | Q24: =MID(HEX2BIN($M24,8),COLUMNS($M24:P24),1) -> 1 | R24: =MID(HEX2BIN($M24,8),COLUMNS($M24:Q24),1) -> 0 | S24: =MID(HEX2BIN($M24,8),COLUMNS($M24:R24),1) -> 0 | T24: =MID(HEX2BIN($M24,8),COLUMNS($M24:S24),1) -> 1 | U24: =MID(HEX2BIN($M24,8),COLUMNS($M24:T24),1) -> 0
C25: 18 | M25: =DEC2HEX(ROW()-$B$1,2) -> 13 | N25: =MID(HEX2BIN($M25,8),COLUMNS($M25:M25),1) -> 0 | O25: =MID(HEX2BIN($M25,8),COLUMNS($M25:N25),1) -> 0 | P25: =MID(HEX2BIN($M25,8),COLUMNS($M25:O25),1) -> 0 | Q25: =MID(HEX2BIN($M25,8),COLUMNS($M25:P25),1) -> 1 | R25: =MID(HEX2BIN($M25,8),COLUMNS($M25:Q25),1) -> 0 | S25: =MID(HEX2BIN($M25,8),COLUMNS($M25:R25),1) -> 0 | T25: =MID(HEX2BIN($M25,8),COLUMNS($M25:S25),1) -> 1 | U25: =MID(HEX2BIN($M25,8),COLUMNS($M25:T25),1) -> 1
C26: 19 | M26: =DEC2HEX(ROW()-$B$1,2) -> 14 | N26: =MID(HEX2BIN($M26,8),COLUMNS($M26:M26),1) -> 0 | O26: =MID(HEX2BIN($M26,8),COLUMNS($M26:N26),1) -> 0 | P26: =MID(HEX2BIN($M26,8),COLUMNS($M26:O26),1) -> 0 | Q26: =MID(HEX2BIN($M26,8),COLUMNS($M26:P26),1) -> 1 | R26: =MID(HEX2BIN($M26,8),COLUMNS($M26:Q26),1) -> 0 | S26: =MID(HEX2BIN($M26,8),COLUMNS($M26:R26),1) -> 1 | T26: =MID(HEX2BIN($M26,8),COLUMNS($M26:S26),1) -> 0 | U26: =MID(HEX2BIN($M26,8),COLUMNS($M26:T26),1) -> 0
C27: 20 | M27: =DEC2HEX(ROW()-$B$1,2) -> 15 | N27: =MID(HEX2BIN($M27,8),COLUMNS($M27:M27),1) -> 0 | O27: =MID(HEX2BIN($M27,8),COLUMNS($M27:N27),1) -> 0 | P27: =MID(HEX2BIN($M27,8),COLUMNS($M27:O27),1) -> 0 | Q27: =MID(HEX2BIN($M27,8),COLUMNS($M27:P27),1) -> 1 | R27: =MID(HEX2BIN($M27,8),COLUMNS($M27:Q27),1) -> 0 | S27: =MID(HEX2BIN($M27,8),COLUMNS($M27:R27),1) -> 1 | T27: =MID(HEX2BIN($M27,8),COLUMNS($M27:S27),1) -> 0 | U27: =MID(HEX2BIN($M27,8),COLUMNS($M27:T27),1) -> 1
C28: 21 | M28: =DEC2HEX(ROW()-$B$1,2) -> 16 | N28: =MID(HEX2BIN($M28,8),COLUMNS($M28:M28),1) -> 0 | O28: =MID(HEX2BIN($M28,8),COLUMNS($M28:N28),1) -> 0 | P28: =MID(HEX2BIN($M28,8),COLUMNS($M28:O28),1) -> 0 | Q28: =MID(HEX2BIN($M28,8),COLUMNS($M28:P28),1) -> 1 | R28: =MID(HEX2BIN($M28,8),COLUMNS($M28:Q28),1) -> 0 | S28: =MID(HEX2BIN($M28,8),COLUMNS($M28:R28),1) -> 1 | T28: =MID(HEX2BIN($M28,8),COLUMNS($M28:S28),1) -> 1 | U28: =MID(HEX2BIN($M28,8),COLUMNS($M28:T28),1) -> 0
C29: 22 | M29: =DEC2HEX(ROW()-$B$1,2) -> 17 | N29: =MID(HEX2BIN($M29,8),COLUMNS($M29:M29),1) -> 0 | O29: =MID(HEX2BIN($M29,8),COLUMNS($M29:N29),1) -> 0 | P29: =MID(HEX2BIN($M29,8),COLUMNS($M29:O29),1) -> 0 | Q29: =MID(HEX2BIN($M29,8),COLUMNS($M29:P29),1) -> 1 | R29: =MID(HEX2BIN($M29,8),COLUMNS($M29:Q29),1) -> 0 | S29: =MID(HEX2BIN($M29,8),COLUMNS($M29:R29),1) -> 1 | T29: =MID(HEX2BIN($M29,8),COLUMNS($M29:S29),1) -> 1 | U29: =MID(HEX2BIN($M29,8),COLUMNS($M29:T29),1) -> 1
M30: =DEC2HEX(ROW()-$B$1,2) -> 18 | N30: =MID(HEX2BIN($M30,8),COLUMNS($M30:M30),1) -> 0 | O30: =MID(HEX2BIN($M30,8),COLUMNS($M30:N30),1) -> 0 | P30: =MID(HEX2BIN($M30,8),COLUMNS($M30:O30),1) -> 0 | Q30: =MID(HEX2BIN($M30,8),COLUMNS($M30:P30),1) -> 1 | R30: =MID(HEX2BIN($M30,8),COLUMNS($M30:Q30),1) -> 1 | S30: =MID(HEX2BIN($M30,8),COLUMNS($M30:R30),1) -> 0 | T30: =MID(HEX2BIN($M30,8),COLUMNS($M30:S30),1) -> 0 | U30: =MID(HEX2BIN($M30,8),COLUMNS($M30:T30),1) -> 0
M31: =DEC2HEX(ROW()-$B$1,2) -> 19 | N31: =MID(HEX2BIN($M31,8),COLUMNS($M31:M31),1) -> 0 | O31: =MID(HEX2BIN($M31,8),COLUMNS($M31:N31),1) -> 0 | P31: =MID(HEX2BIN($M31,8),COLUMNS($M31:O31),1) -> 0 | Q31: =MID(HEX2BIN($M31,8),COLUMNS($M31:P31),1) -> 1 | R31: =MID(HEX2BIN($M31,8),COLUMNS($M31:Q31),1) -> 1 | S31: =MID(HEX2BIN($M31,8),COLUMNS($M31:R31),1) -> 0 | T31: =MID(HEX2BIN($M31,8),COLUMNS($M31:S31),1) -> 0 | U31: =MID(HEX2BIN($M31,8),COLUMNS($M31:T31),1) -> 1
M32: =DEC2HEX(ROW()-$B$1,2) -> 1A | N32: =MID(HEX2BIN($M32,8),COLUMNS($M32:M32),1) -> 0 | O32: =MID(HEX2BIN($M32,8),COLUMNS($M32:N32),1) -> 0 | P32: =MID(HEX2BIN($M32,8),COLUMNS($M32:O32),1) -> 0 | Q32: =MID(HEX2BIN($M32,8),COLUMNS($M32:P32),1) -> 1 | R32: =MID(HEX2BIN($M32,8),COLUMNS($M32:Q32),1) -> 1 | S32: =MID(HEX2BIN($M32,8),COLUMNS($M32:R32),1) -> 0 | T32: =MID(HEX2BIN($M32,8),COLUMNS($M32:S32),1) -> 1 | U32: =MID(HEX2BIN($M32,8),COLUMNS($M32:T32),1) -> 0
M33: =DEC2HEX(ROW()-$B$1,2) -> 1B | N33: =MID(HEX2BIN($M33,8),COLUMNS($M33:M33),1) -> 0 | O33: =MID(HEX2BIN($M33,8),COLUMNS($M33:N33),1) -> 0 | P33: =MID(HEX2BIN($M33,8),COLUMNS($M33:O33),1) -> 0 | Q33: =MID(HEX2BIN($M33,8),COLUMNS($M33:P33),1) -> 1 | R33: =MID(HEX2BIN($M33,8),COLUMNS($M33:Q33),1) -> 1 | S33: =MID(HEX2BIN($M33,8),COLUMNS($M33:R33),1) -> 0 | T33: =MID(HEX2BIN($M33,8),COLUMNS($M33:S33),1) -> 1 | U33: =MID(HEX2BIN($M33,8),COLUMNS($M33:T33),1) -> 1
M34: =DEC2HEX(ROW()-$B$1,2) -> 1C | N34: =MID(HEX2BIN($M34,8),COLUMNS($M34:M34),1) -> 0 | O34: =MID(HEX2BIN($M34,8),COLUMNS($M34:N34),1) -> 0 | P34: =MID(HEX2BIN($M34,8),COLUMNS($M34:O34),1) -> 0 | Q34: =MID(HEX2BIN($M34,8),COLUMNS($M34:P34),1) -> 1 | R34: =MID(HEX2BIN($M34,8),COLUMNS($M34:Q34),1) -> 1 | S34: =MID(HEX2BIN($M34,8),COLUMNS($M34:R34),1) -> 1 | T34: =MID(HEX2BIN($M34,8),COLUMNS($M34:S34),1) -> 0 | U34: =MID(HEX2BIN($M34,8),COLUMNS($M34:T34),1) -> 0
M35: =DEC2HEX(ROW()-$B$1,2) -> 1D | N35: =MID(HEX2BIN($M35,8),COLUMNS($M35:M35),1) -> 0 | O35: =MID(HEX2BIN($M35,8),COLUMNS($M35:N35),1) -> 0 | P35: =MID(HEX2BIN($M35,8),COLUMNS($M35:O35),1) -> 0 | Q35: =MID(HEX2BIN($M35,8),COLUMNS($M35:P35),1) -> 1 | R35: =MID(HEX2BIN($M35,8),COLUMNS($M35:Q35),1) -> 1 | S35: =MID(HEX2BIN($M35,8),COLUMNS($M35:R35),1) -> 1 | T35: =MID(HEX2BIN($M35,8),COLUMNS($M35:S35),1) -> 0 | U35: =MID(HEX2BIN($M35,8),COLUMNS($M35:T35),1) -> 1
M36: =DEC2HEX(ROW()-$B$1,2) -> 1E | N36: =MID(HEX2BIN($M36,8),COLUMNS($M36:M36),1) -> 0 | O36: =MID(HEX2BIN($M36,8),COLUMNS($M36:N36),1) -> 0 | P36: =MID(HEX2BIN($M36,8),COLUMNS($M36:O36),1) -> 0 | Q36: =MID(HEX2BIN($M36,8),COLUMNS($M36:P36),1) -> 1 | R36: =MID(HEX2BIN($M36,8),COLUMNS($M36:Q36),1) -> 1 | S36: =MID(HEX2BIN($M36,8),COLUMNS($M36:R36),1) -> 1 | T36: =MID(HEX2BIN($M36,8),COLUMNS($M36:S36),1) -> 1 | U36: =MID(HEX2BIN($M36,8),COLUMNS($M36:T36),1) -> 0
M37: =DEC2HEX(ROW()-$B$1,2) -> 1F | N37: =MID(HEX2BIN($M37,8),COLUMNS($M37:M37),1) -> 0 | O37: =MID(HEX2BIN($M37,8),COLUMNS($M37:N37),1) -> 0 | P37: =MID(HEX2BIN($M37,8),COLUMNS($M37:O37),1) -> 0 | Q37: =MID(HEX2BIN($M37,8),COLUMNS($M37:P37),1) -> 1 | R37: =MID(HEX2BIN($M37,8),COLUMNS($M37:Q37),1) -> 1 | S37: =MID(HEX2BIN($M37,8),COLUMNS($M37:R37),1) -> 1 | T37: =MID(HEX2BIN($M37,8),COLUMNS($M37:S37),1) -> 1 | U37: =MID(HEX2BIN($M37,8),COLUMNS($M37:T37),1) -> 1
M38: =DEC2HEX(ROW()-$B$1,2) -> 20 | N38: =MID(HEX2BIN($M38,8),COLUMNS($M38:M38),1) -> 0 | O38: =MID(HEX2BIN($M38,8),COLUMNS($M38:N38),1) -> 0 | P38: =MID(HEX2BIN($M38,8),COLUMNS($M38:O38),1) -> 1 | Q38: =MID(HEX2BIN($M38,8),COLUMNS($M38:P38),1) -> 0 | R38: =MID(HEX2BIN($M38,8),COLUMNS($M38:Q38),1) -> 0 | S38: =MID(HEX2BIN($M38,8),COLUMNS($M38:R38),1) -> 0 | T38: =MID(HEX2BIN($M38,8),COLUMNS($M38:S38),1) -> 0 | U38: =MID(HEX2BIN($M38,8),COLUMNS($M38:T38),1) -> 0
M39: =DEC2HEX(ROW()-$B$1,2) -> 21 | N39: =MID(HEX2BIN($M39,8),COLUMNS($M39:M39),1) -> 0 | O39: =MID(HEX2BIN($M39,8),COLUMNS($M39:N39),1) -> 0 | P39: =MID(HEX2BIN($M39,8),COLUMNS($M39:O39),1) -> 1 | Q39: =MID(HEX2BIN($M39,8),COLUMNS($M39:P39),1) -> 0 | R39: =MID(HEX2BIN($M39,8),COLUMNS($M39:Q39),1) -> 0 | S39: =MID(HEX2BIN($M39,8),COLUMNS($M39:R39),1) -> 0 | T39: =MID(HEX2BIN($M39,8),COLUMNS($M39:S39),1) -> 0 | U39: =MID(HEX2BIN($M39,8),COLUMNS($M39:T39),1) -> 1
M40: =DEC2HEX(ROW()-$B$1,2) -> 22 | N40: =MID(HEX2BIN($M40,8),COLUMNS($M40:M40),1) -> 0 | O40: =MID(HEX2BIN($M40,8),COLUMNS($M40:N40),1) -> 0 | P40: =MID(HEX2BIN($M40,8),COLUMNS($M40:O40),1) -> 1 | Q40: =MID(HEX2BIN($M40,8),COLUMNS($M40:P40),1) -> 0 | R40: =MID(HEX2BIN($M40,8),COLUMNS($M40:Q40),1) -> 0 | S40: =MID(HEX2BIN($M40,8),COLUMNS($M40:R40),1) -> 0 | T40: =MID(HEX2BIN($M40,8),COLUMNS($M40:S40),1) -> 1 | U40: =MID(HEX2BIN($M40,8),COLUMNS($M40:T40),1) -> 0
...

Sheet DB
A1: Battery Capacity | D1: BatteryVariant | L1: PackSupplier
A2: Capacity | B2: Number | C2: Project | D2: BMSsupplier | F2: BMSmfg | H2: BALcellPartNum | J2: BatteryConfig | L2: PackSupplier
A3: 0 | B3: RESERVED 1 | D3: BAL | E3: Bajaj | F3: BAL | G3: Bajaj | H3: RESERVED 1 | I3: RESERVED 1 | J3: FIX | L3: BAL R&D | M3: Bajaj R&D
A4: 1 | B4: 2.96kWh | D4: RESERVED 1 | E4: RESERVED 1 | F4: RESERVED 1 | G4: RESERVED 1 | H4: RESERVED 2 | I4: RESERVED 2 | J4: SWP | L4: BAL | M4: Bajaj
A5: 2 | B5: 5.9 kWh | D5: RESERVED 2 | E5: RESERVED 2 | F5: RESERVED 2 | G5: RESERVED 2 | H5: RESERVED 3 | I5: RESERVED 3 | L5: RESERVED 1 | M5: RESERVED 1
A6: 3 | B6: 8.9 kWh | C6: R116C | D6: RESERVED 3 | E6: RESERVED 3 | F6: RNTEC | G6: Gotion - RNTEC | H6: RESERVED 4 | I6: RESERVED 4 | L6: GOTION | M6: Gotion
A7: 4 | B7: 11.8 kWh | C7: R127A | D7: GOTION | E7: Gotion | F7: PENERGY | G7: Gotion - Penergy | H7: RESERVED 5 | I7: RESERVED 5 | L7: TACO-EV | M7: Tata Autocomp
A8: 5 | B8: 1.07 kWh | C8: Shared Mobility | D8: RESERVED 4 | E8: RESERVED 4 | F8: RESERVED 3 | G8: RESERVED 3 | H8: RESERVED 6 | I8: RESERVED 6 | L8: RESERVED 2 | M8: RESERVED 2
A9: 6 | B9: RESERVED 2 | D9: RESERVED 5 | E9: RESERVED 5 | F9: RESERVED 4 | G9: RESERVED 4 | H9: GL405132_21 | I9: Gotion 21Ah
A10: 7 | B10: RESERVED 3 | F10: RESERVED 5 | G10: RESERVED 5 | H10: PRF027135_145 | I10: Gotion 14.5Ah
A11: 8 | B11: RESERVED 4 | F11: RESERVED 6 | G11: RESERVED 6 | H11: RESERVED7 | I11: RESERVED7
A12: 9 | B12: RESERVED 5 | F12: DBG | G12: TACO- DBG | H12: RESERVED8 | I12: RESERVED8
A13: 10 | B13: RESERVED 6 | H13: RESERVED9 | I13: RESERVED9
A14: 11 | B14: RESERVED 7 | H14: RESERVED10 | I14: RESERVED10
A15: 12 | B15: RESERVED 8 | H15: RESERVED11 | I15: RESERVED11
A16: 13 | B16: 12.1 kWh | C16: R125D/ R116G | H16: RESERVED12 | I16: RESERVED12
A17: 14 | B17: 9.2 kWh | C17: R116K | H17: Gotion_14.8 | I17: Gotion Cylindrical 14.8Ah
A18: 15 | B18: 12.2 kWh | C18: R127D | H18: Gotion_67 | I18: Gotion Prismatic 67Ah
A19: 16 | B19: 9.2 kWh (Side lug mounting) | C19: R116L - 9.2kWh
A20: 17 | B20: 12.1kWh (Side lug mounting) | C20: R116L - 12.1kWh
A21: 18 | B21: 10.3 kWh (Prismatic) | C21: 10.3 kWh (Prismatic)
A22: 19 | B22: 13.72 kWh (Prismatic) | C22: 13.72 kWh (Prismatic)
A23: 20 | B23: 10.3 kWh (Heater) | C23: 10.3 kWh (Heater)
A24: 21 | B24: 13.72 kWh (Heater) | C24: 13.72 kWh (Heater)
A25: 22 | B25: 6.1 kWh | C25: R119B
A26: 23 | B26: 6.8 kWh | C26: R119H
A27: 24
A28: 25
A29: 26
A30: 27
A31: 28

Sheet BINuniverse
A1: Sr. | B1: Battery Capacity | C1: BatteryVariant | G1: PackSupplier | H1: AssemblyInfo | K1: Plant line | L1: Serial Number | M1: BIN | N1: Remarks
C2: BMSsupplier | D2: BMSmfg | E2: BALcellPartNum | F2: BatteryConfig | H2: Year (YYYY) | I2: Month (MM) | J2: Date (DD)
A3: 1 | B3: 2 | C3: GOTION | D3: PENERGY | E3: PRF027135_145 | F3: FIX | G3: TACO-EV | H3: 2023 | I3: 5 | J3: 16 | K3: 1 | L3: 1 | M3: =CONCATENATE(DEC2HEX(B3),VLOOKUP(CONCATENATE(C3,"_",D3,"_",E3,"_",F3),Format!L:M,2,FALSE),VLOOKUP(G3,Format!V:W,2,FALSE),CONCATENATE(BIN2HEX(LEFT(CONCATENATE(DEC2BIN(H3-2000,7),DEC2BIN(I3,4),DEC2BIN(J3,5)),4)),BIN2HEX(LEFT(RIGHT(CONCATENATE(DEC2BIN(H3-2000,7),DEC2BIN(I3,4),DEC2BIN(J3,5)),12),4)),BIN2HEX(LEFT(RIGHT(CONCATENATE(DEC2BIN(H3-2000,7),DEC2BIN(I3,4),DEC2BIN(J3,5)),8),4)),BIN2HEX(RIGHT(CONCATENATE(DEC2BIN(H3-2000,7),DEC2BIN(I3,4),DEC2BIN(J3,5)),4))),DEC2HEX(K3),DEC2HEX(L3,4)) -> 20242EB010001 | N3: Gotion 5.9 kWh
A4: 2 | B4: 3 | C4: GOTION | D4: PENERGY | E4: PRF027135_145 | F4: FIX | G4: TACO-EV | H4: 2023 | I4: 5 | J4: 16 | K4: 1 | L4: 1 | M4: =CONCATENATE(DEC2HEX(B4),VLOOKUP(CONCATENATE(C4,"_",D4,"_",E4,"_",F4),Format!L:M,2,FALSE),VLOOKUP(G4,Format!V:W,2,FALSE),CONCATENATE(BIN2HEX(LEFT(CONCATENATE(DEC2BIN(H4-2000,7),DEC2BIN(I4,4),DEC2BIN(J4,5)),4)),BIN2HEX(LEFT(RIGHT(CONCATENATE(DEC2BIN(H4-2000,7),DEC2BIN(I4,4),DEC2BIN(J4,5)),12),4)),BIN2HEX(LEFT(RIGHT(CONCATENATE(DEC2BIN(H4-2000,7),DEC2BIN(I4,4),DEC2BIN(J4,5)),8),4)),BIN2HEX(RIGHT(CONCATENATE(DEC2BIN(H4-2000,7),DEC2BIN(I4,4),DEC2BIN(J4,5)),4))),DEC2HEX(K4),DEC2HEX(L4,4)) -> 30242EB010001 | N4: Gotion 8.9 kWh
A5: 3 | B5: 4 | C5: GOTION | D5: PENERGY | E5: PRF027135_145 | F5: FIX | G5: TACO-EV | H5: 2023 | I5: 5 | J5: 16 | K5: 1 | L5: 1 | M5: =CONCATENATE(DEC2HEX(B5),VLOOKUP(CONCATENATE(C5,"_",D5,"_",E5,"_",F5),Format!L:M,2,FALSE),VLOOKUP(G5,Format!V:W,2,FALSE),CONCATENATE(BIN2HEX(LEFT(CONCATENATE(DEC2BIN(H5-2000,7),DEC2BIN(I5,4),DEC2BIN(J5,5)),4)),BIN2HEX(LEFT(RIGHT(CONCATENATE(DEC2BIN(H5-2000,7),DEC2BIN(I5,4),DEC2BIN(J5,5)),12),4)),BIN2HEX(LEFT(RIGHT(CONCATENATE(DEC2BIN(H5-2000,7),DEC2BIN(I5,4),DEC2BIN(J5,5)),8),4)),BIN2HEX(RIGHT(CONCATENATE(DEC2BIN(H5-2000,7),DEC2BIN(I5,4),DEC2BIN(J5,5)),4))),DEC2HEX(K5),DEC2HEX(L5,4)) -> 40242EB010001 | N5: Gotion 11.8 kWh
A6: 4 | B6: 5 | C6: GOTION | D6: RNTEC | E6: GL405132_21 | F6: SWP | G6: TACO-EV | H6: 2023 | I6: 5 | J6: 16 | K6: 1 | L6: 1 | M6: =CONCATENATE(DEC2HEX(B6),VLOOKUP(CONCATENATE(C6,"_",D6,"_",E6,"_",F6),Format!L:M,2,FALSE),VLOOKUP(G6,Format!V:W,2,FALSE),CONCATENATE(BIN2HEX(LEFT(CONCATENATE(DEC2BIN(H6-2000,7),DEC2BIN(I6,4),DEC2BIN(J6,5)),4)),BIN2HEX(LEFT(RIGHT(CONCATENATE(DEC2BIN(H6-2000,7),DEC2BIN(I6,4),DEC2BIN(J6,5)),12),4)),BIN2HEX(LEFT(RIGHT(CONCATENATE(DEC2BIN(H6-2000,7),DEC2BIN(I6,4),DEC2BIN(J6,5)),8),4)),BIN2HEX(RIGHT(CONCATENATE(DEC2BIN(H6-2000,7),DEC2BIN(I6,4),DEC2BIN(J6,5)),4))),DEC2HEX(K6),DEC2HEX(L6,4)) -> 50342EB010001 | N6: Gotion 1.07 Shared Mobility
A7: 5 | B7: 13 | C7: GOTION | D7: PENERGY | E7: Gotion_14.8 | F7: FIX | G7: TACO-EV | H7: 2026 | I7: 3 | J7: 30 | K7: 1 | L7: 1 | M7: =CONCATENATE(DEC2HEX(B7),VLOOKUP(CONCATENATE(C7,"_",D7,"_",E7,"_",F7),Format!L:M,2,FALSE),VLOOKUP(G7,Format!V:W,2,FALSE),CONCATENATE(BIN2HEX(LEFT(CONCATENATE(DEC2BIN(H7-2000,7),DEC2BIN(I7,4),DEC2BIN(J7,5)),4)),BIN2HEX(LEFT(RIGHT(CONCATENATE(DEC2BIN(H7-2000,7),DEC2BIN(I7,4),DEC2BIN(J7,5)),12),4)),BIN2HEX(LEFT(RIGHT(CONCATENATE(DEC2BIN(H7-2000,7),DEC2BIN(I7,4),DEC2BIN(J7,5)),8),4)),BIN2HEX(RIGHT(CONCATENATE(DEC2BIN(H7-2000,7),DEC2BIN(I7,4),DEC2BIN(J7,5)),4))),DEC2HEX(K7),DEC2HEX(L7,4)) -> D0E4347E10001 | N7: Gotion 12.1kWh pack
A8: 6 | B8: 14 | C8: GOTION | D8: PENERGY | E8: Gotion_14.8 | F8: FIX | G8: TACO-EV | H8: 2026 | I8: 3 | J8: 30 | K8: 1 | L8: 1 | M8: =CONCATENATE(DEC2HEX(B8),VLOOKUP(CONCATENATE(C8,"_",D8,"_",E8,"_",F8),Format!L:M,2,FALSE),VLOOKUP(G8,Format!V:W,2,FALSE),CONCATENATE(BIN2HEX(LEFT(CONCATENATE(DEC2BIN(H8-2000,7),DEC2BIN(I8,4),DEC2BIN(J8,5)),4)),BIN2HEX(LEFT(RIGHT(CONCATENATE(DEC2BIN(H8-2000,7),DEC2BIN(I8,4),DEC2BIN(J8,5)),12),4)),BIN2HEX(LEFT(RIGHT(CONCATENATE(DEC2BIN(H8-2000,7),DEC2BIN(I8,4),DEC2BIN(J8,5)),8),4)),BIN2HEX(RIGHT(CONCATENATE(DEC2BIN(H8-2000,7),DEC2BIN(I8,4),DEC2BIN(J8,5)),4))),DEC2HEX(K8),DEC2HEX(L8,4)) -> E0E4347E10001 | N8: Gotion 9.2 kWh_14.8Ah cells
A9: 7 | B9: 15 | C9: GOTION | D9: PENERGY | E9: Gotion_14.8 | F9: FIX | G9: TACO-EV | H9: 2026 | I9: 3 | J9: 30 | K9: 1 | L9: 1 | M9: =CONCATENATE(DEC2HEX(B9),VLOOKUP(CONCATENATE(C9,"_",D9,"_",E9,"_",F9),Format!L:M,2,FALSE),VLOOKUP(G9,Format!V:W,2,FALSE),CONCATENATE(BIN2HEX(LEFT(CONCATENATE(DEC2BIN(H9-2000,7),DEC2BIN(I9,4),DEC2BIN(J9,5)),4)),BIN2HEX(LEFT(RIGHT(CONCATENATE(DEC2BIN(H9-2000,7),DEC2BIN(I9,4),DEC2BIN(J9,5)),12),4)),BIN2HEX(LEFT(RIGHT(CONCATENATE(DEC2BIN(H9-2000,7),DEC2BIN(I9,4),DEC2BIN(J9,5)),8),4)),BIN2HEX(RIGHT(CONCATENATE(DEC2BIN(H9-2000,7),DEC2BIN(I9,4),DEC2BIN(J9,5)),4))),DEC2HEX(K9),DEC2HEX(L9,4)) -> F0E4347E10001 | N9: Gotion 12.2 kWh_14.8Ah cells
A10: 8 | B10: 16 | C10: GOTION | D10: PENERGY | E10: Gotion_14.8 | F10: FIX | G10: TACO-EV | H10: 2026 | I10: 3 | J10: 30 | K10: 1 | L10: 1 | M10: =CONCATENATE(DEC2HEX(B10),VLOOKUP(CONCATENATE(C10,"_",D10,"_",E10,"_",F10),Format!L:M,2,FALSE),VLOOKUP(G10,Format!V:W,2,FALSE),CONCATENATE(BIN2HEX(LEFT(CONCATENATE(DEC2BIN(H10-2000,7),DEC2BIN(I10,4),DEC2BIN(J10,5)),4)),BIN2HEX(LEFT(RIGHT(CONCATENATE(DEC2BIN(H10-2000,7),DEC2BIN(I10,4),DEC2BIN(J10,5)),12),4)),BIN2HEX(LEFT(RIGHT(CONCATENATE(DEC2BIN(H10-2000,7),DEC2BIN(I10,4),DEC2BIN(J10,5)),8),4)),BIN2HEX(RIGHT(CONCATENATE(DEC2BIN(H10-2000,7),DEC2BIN(I10,4),DEC2BIN(J10,5)),4))),DEC2HEX(K10),DEC2HEX(L10,4)) -> 100E4347E10001 | N10: Gotion 9.2 kWh (Side lug mounting)_14.8Ah cells
A11: 9 | B11: 17 | C11: GOTION | D11: PENERGY | E11: Gotion_14.8 | F11: FIX | G11: TACO-EV | H11: 2026 | I11: 3 | J11: 30 | K11: 1 | L11: 1 | M11: =CONCATENATE(DEC2HEX(B11),VLOOKUP(CONCATENATE(C11,"_",D11,"_",E11,"_",F11),Format!L:M,2,FALSE),VLOOKUP(G11,Format!V:W,2,FALSE),CONCATENATE(BIN2HEX(LEFT(CONCATENATE(DEC2BIN(H11-2000,7),DEC2BIN(I11,4),DEC2BIN(J11,5)),4)),BIN2HEX(LEFT(RIGHT(CONCATENATE(DEC2BIN(H11-2000,7),DEC2BIN(I11,4),DEC2BIN(J11,5)),12),4)),BIN2HEX(LEFT(RIGHT(CONCATENATE(DEC2BIN(H11-2000,7),DEC2BIN(I11,4),DEC2BIN(J11,5)),8),4)),BIN2HEX(RIGHT(CONCATENATE(DEC2BIN(H11-2000,7),DEC2BIN(I11,4),DEC2BIN(J11,5)),4))),DEC2HEX(K11),DEC2HEX(L11,4)) -> 110E4347E10001 | N11: Gotion 12.1kWh (Side lug mounting)_14.8Ah cells
A12: 10 | B12: 18 | C12: GOTION | D12: PENERGY | E12: Gotion_67 | F12: FIX | G12: TACO-EV | H12: 2026 | I12: 3 | J12: 30 | K12: 1 | L12: 1 | M12: =CONCATENATE(DEC2HEX(B12),VLOOKUP(CONCATENATE(C12,"_",D12,"_",E12,"_",F12),Format!L:M,2,FALSE),VLOOKUP(G12,Format!V:W,2,FALSE),CONCATENATE(BIN2HEX(LEFT(CONCATENATE(DEC2BIN(H12-2000,7),DEC2BIN(I12,4),DEC2BIN(J12,5)),4)),BIN2HEX(LEFT(RIGHT(CONCATENATE(DEC2BIN(H12-2000,7),DEC2BIN(I12,4),DEC2BIN(J12,5)),12),4)),BIN2HEX(LEFT(RIGHT(CONCATENATE(DEC2BIN(H12-2000,7),DEC2BIN(I12,4),DEC2BIN(J12,5)),8),4)),BIN2HEX(RIGHT(CONCATENATE(DEC2BIN(H12-2000,7),DEC2BIN(I12,4),DEC2BIN(J12,5)),4))),DEC2HEX(K12),DEC2HEX(L12,4)) -> 120F4347E10001 | N12: Gotion 10.3 kWh (Prismatic)_67Ah cells
A13: 11 | B13: 19 | C13: GOTION | D13: PENERGY | E13: Gotion_67 | F13: FIX | G13: TACO-EV | H13: 2026 | I13: 3 | J13: 30 | K13: 1 | L13: 1 | M13: =CONCATENATE(DEC2HEX(B13),VLOOKUP(CONCATENATE(C13,"_",D13,"_",E13,"_",F13),Format!L:M,2,FALSE),VLOOKUP(G13,Format!V:W,2,FALSE),CONCATENATE(BIN2HEX(LEFT(CONCATENATE(DEC2BIN(H13-2000,7),DEC2BIN(I13,4),DEC2BIN(J13,5)),4)),BIN2HEX(LEFT(RIGHT(CONCATENATE(DEC2BIN(H13-2000,7),DEC2BIN(I13,4),DEC2BIN(J13,5)),12),4)),BIN2HEX(LEFT(RIGHT(CONCATENATE(DEC2BIN(H13-2000,7),DEC2BIN(I13,4),DEC2BIN(J13,5)),8),4)),BIN2HEX(RIGHT(CONCATENATE(DEC2BIN(H13-2000,7),DEC2BIN(I13,4),DEC2BIN(J13,5)),4))),DEC2HEX(K13),DEC2HEX(L13,4)) -> 130F4347E10001 | N13: Gotion 13.72 kWh (Prismatic)_67Ah cells
A14: 12 | B14: 20 | C14: GOTION | D14: PENERGY | E14: Gotion_67 | F14: FIX | G14: TACO-EV | H14: 2026 | I14: 3 | J14: 30 | K14: 1 | L14: 1 | M14: =CONCATENATE(DEC2HEX(B14),VLOOKUP(CONCATENATE(C14,"_",D14,"_",E14,"_",F14),Format!L:M,2,FALSE),VLOOKUP(G14,Format!V:W,2,FALSE),CONCATENATE(BIN2HEX(LEFT(CONCATENATE(DEC2BIN(H14-2000,7),DEC2BIN(I14,4),DEC2BIN(J14,5)),4)),BIN2HEX(LEFT(RIGHT(CONCATENATE(DEC2BIN(H14-2000,7),DEC2BIN(I14,4),DEC2BIN(J14,5)),12),4)),BIN2HEX(LEFT(RIGHT(CONCATENATE(DEC2BIN(H14-2000,7),DEC2BIN(I14,4),DEC2BIN(J14,5)),8),4)),BIN2HEX(RIGHT(CONCATENATE(DEC2BIN(H14-2000,7),DEC2BIN(I14,4),DEC2BIN(J14,5)),4))),DEC2HEX(K14),DEC2HEX(L14,4)) -> 140F4347E10001 | N14: Gotion 10.3 kWh (Heater)_67Ah cells
... A18: 6 | B18: 14 | C18: GOTION | D18: DBG | E18: Gotion_14.8 | F18: FIX | G18: TACO-EV | H18: 2026 | I18: 3 | J18: 30 | K18: 1 | L18: 1 | M18: =CONCATENATE(DEC2HEX(B18),VLOOKUP(CONCATENATE(C18,"_",D18,"_",E18,"_",F18),Format!L:M,2,FALSE),VLOOKUP(G18,Format!V:W,2,FALSE),CONCATENATE(BIN2HEX(LEFT(CONCATENATE(DEC2BIN(H18-2000,7),DEC2BIN(I18,4),DEC2BIN(J18,5)),4)),BIN2HEX(LEFT(RIGHT(CONCATENATE(DEC2BIN(H18-2000,7),DEC2BIN(I18,4),DEC2BIN(J18,5)),12),4)),BIN2HEX(LEFT(RIGHT(CONCATENATE(DEC2BIN(H18-2000,7),DEC2BIN(I18,4),DEC2BIN(J18,5)),8),4)),BIN2HEX(RIGHT(CONCATENATE(DEC2BIN(H18-2000,7),DEC2BIN(I18,4),DEC2BIN(J18,5)),4))),DEC2HEX(K18),DEC2HEX(L18,4)) -> E104347E10001 | N18: Gotion 9.2 kWh_14.8Ah cells

Sheet VolumeEstimation
D2: 2W | E2: 3W | F2: Total
B3: Vehicles/year | D3: 3000000 | E3: 1000000
B4: %EV | D4: 0.01 | E4: 0.03
D5: =D3*D4 -> 30000 | E5: =E3*E4 -> 30000
B6: #batteries/vehicle | D6: 1 | E6: 3
B7: swap fraction | D7: 0.25 | E7: 0.75
B8: swap factor | D8: 2.5 | E8: 2.5
B9: fixed replacement factor | D9: 1.01 | E9: 1.01
B10: #batteries/year | D10: =D5*D7*D6*D8+D5*(1-D7)*D6*D9 -> 41475 | E10: =E5*E7*E6*E8+E5*(1-E7)*E6*E9 -> 191475
B11: #batteries/month | D11: =D10/10 -> 4147.5 | E11: =E10/10 -> 19147.5 | F11: =D11+E11 -> 23295
B12: nYears | F12: 10
B13: compounded @ | F13: 0.1
B14: #batteries total | F14: =F11*(1-(1+F13)^F12)/(1-(1+F13)) -> 371262.31
B15: #bits required | F15: =LOG(F14,2) -> 18.502079
